2017-06-13 22:44:04,154 (e:\Temp\python) [log.py:151] INFO <=> Using Software Version: commit string could not be parsed, not valid json
2017-06-13 22:44:31,756 (e:\Temp\python) [log.py:151] INFO <=> Using Software Version: commit string could not be parsed, not valid json
2017-06-13 22:45:12,500 (e:\Temp\python) [log.py:151] INFO <=> Using Software Version: commit string could not be parsed, not valid json
2017-06-13 22:47:00,273 (e:\Temp\python) [log.py:151] INFO <=> Using Software Version: commit string could not be parsed, not valid json
2017-06-13 22:48:56,588 (e:\Temp\python) [log.py:151] INFO <=> Using Software Version: commit string could not be parsed, not valid json
2017-06-13 22:49:53,411 (e:\Temp\python) [log.py:151] INFO <=> Using Software Version: commit string could not be parsed, not valid json
2017-06-13 22:50:22,365 (e:\Temp\python) [log.py:78] ERROR <=> (2003, "Can't connect to MySQL server on 'localhost' ([Errno 10061] No connection could be made because the target machine actively refused it)")
Traceback (most recent call last):
  File "e:\Temp\python\Current Source Code - clickMD.ca\database.py", line 31, in connect
    connect_timeout=15)
  File "C:\Python27\lib\site-packages\pymysql\__init__.py", line 90, in Connect
    return Connection(*args, **kwargs)
  File "C:\Python27\lib\site-packages\pymysql\connections.py", line 706, in __init__
    self.connect()
  File "C:\Python27\lib\site-packages\pymysql\connections.py", line 963, in connect
    raise exc
OperationalError: (2003, "Can't connect to MySQL server on 'localhost' ([Errno 10061] No connection could be made because the target machine actively refused it)")
2017-06-13 23:00:10,936 (e:\Temp\python) [log.py:78] ERROR <=> (2003, "Can't connect to MySQL server on 'localhost' ([Errno 10061] No connection could be made because the target machine actively refused it)")
Traceback (most recent call last):
  File "e:\Temp\python\Current Source Code - clickMD.ca\database.py", line 31, in connect
    connect_timeout=15)
  File "C:\Python27\lib\site-packages\pymysql\__init__.py", line 90, in Connect
    return Connection(*args, **kwargs)
  File "C:\Python27\lib\site-packages\pymysql\connections.py", line 706, in __init__
    self.connect()
  File "C:\Python27\lib\site-packages\pymysql\connections.py", line 963, in connect
    raise exc
OperationalError: (2003, "Can't connect to MySQL server on 'localhost' ([Errno 10061] No connection could be made because the target machine actively refused it)")
2017-06-13 23:14:35,204 (e:\Temp\python) [log.py:151] INFO <=> Using Software Version: commit string could not be parsed, not valid json
2017-06-13 23:15:17,986 (e:\Temp\python) [log.py:78] ERROR <=> (2003, "Can't connect to MySQL server on 'localhost' ([Errno 10061] No connection could be made because the target machine actively refused it)")
Traceback (most recent call last):
  File "e:\Temp\python\Current Source Code - clickMD.ca\database.py", line 31, in connect
    connect_timeout=15)
  File "C:\Python27\lib\site-packages\pymysql\__init__.py", line 90, in Connect
    return Connection(*args, **kwargs)
  File "C:\Python27\lib\site-packages\pymysql\connections.py", line 706, in __init__
    self.connect()
  File "C:\Python27\lib\site-packages\pymysql\connections.py", line 963, in connect
    raise exc
OperationalError: (2003, "Can't connect to MySQL server on 'localhost' ([Errno 10061] No connection could be made because the target machine actively refused it)")
2017-06-13 23:15:26,138 (e:\Temp\python) [log.py:78] ERROR <=> (2003, "Can't connect to MySQL server on 'localhost' ([Errno 10061] No connection could be made because the target machine actively refused it)")
Traceback (most recent call last):
  File "e:\Temp\python\Current Source Code - clickMD.ca\database.py", line 31, in connect
    connect_timeout=15)
  File "C:\Python27\lib\site-packages\pymysql\__init__.py", line 90, in Connect
    return Connection(*args, **kwargs)
  File "C:\Python27\lib\site-packages\pymysql\connections.py", line 706, in __init__
    self.connect()
  File "C:\Python27\lib\site-packages\pymysql\connections.py", line 963, in connect
    raise exc
OperationalError: (2003, "Can't connect to MySQL server on 'localhost' ([Errno 10061] No connection could be made because the target machine actively refused it)")
2017-06-13 23:22:03,572 (e:\Temp\python) [log.py:78] ERROR <=> (2003, "Can't connect to MySQL server on 'localhost' ([Errno 10061] No connection could be made because the target machine actively refused it)")
Traceback (most recent call last):
  File "e:\Temp\python\Current Source Code - clickMD.ca\database.py", line 31, in connect
    connect_timeout=15)
  File "C:\Python27\lib\site-packages\pymysql\__init__.py", line 90, in Connect
    return Connection(*args, **kwargs)
  File "C:\Python27\lib\site-packages\pymysql\connections.py", line 706, in __init__
    self.connect()
  File "C:\Python27\lib\site-packages\pymysql\connections.py", line 963, in connect
    raise exc
OperationalError: (2003, "Can't connect to MySQL server on 'localhost' ([Errno 10061] No connection could be made because the target machine actively refused it)")
2017-06-13 23:22:42,918 (e:\Temp\python) [log.py:78] ERROR <=> (2003, "Can't connect to MySQL server on 'localhost' ([Errno 10061] No connection could be made because the target machine actively refused it)")
Traceback (most recent call last):
  File "e:\Temp\python\Current Source Code - clickMD.ca\database.py", line 31, in connect
    connect_timeout=15)
  File "C:\Python27\lib\site-packages\pymysql\__init__.py", line 90, in Connect
    return Connection(*args, **kwargs)
  File "C:\Python27\lib\site-packages\pymysql\connections.py", line 706, in __init__
    self.connect()
  File "C:\Python27\lib\site-packages\pymysql\connections.py", line 963, in connect
    raise exc
OperationalError: (2003, "Can't connect to MySQL server on 'localhost' ([Errno 10061] No connection could be made because the target machine actively refused it)")
2017-06-13 23:37:23,313 (e:\Temp\python) [log.py:78] ERROR <=> (1045, u"Access denied for user 'dataesp'@'localhost' (using password: YES)")
Traceback (most recent call last):
  File "e:\Temp\python\Current Source Code - clickMD.ca\database.py", line 31, in connect
    connect_timeout=15)
  File "C:\Python27\lib\site-packages\pymysql\__init__.py", line 90, in Connect
    return Connection(*args, **kwargs)
  File "C:\Python27\lib\site-packages\pymysql\connections.py", line 706, in __init__
    self.connect()
  File "C:\Python27\lib\site-packages\pymysql\connections.py", line 932, in connect
    self._request_authentication()
  File "C:\Python27\lib\site-packages\pymysql\connections.py", line 1152, in _request_authentication
    auth_packet = self._read_packet()
  File "C:\Python27\lib\site-packages\pymysql\connections.py", line 1014, in _read_packet
    packet.check_error()
  File "C:\Python27\lib\site-packages\pymysql\connections.py", line 393, in check_error
    err.raise_mysql_exception(self._data)
  File "C:\Python27\lib\site-packages\pymysql\err.py", line 107, in raise_mysql_exception
    raise errorclass(errno, errval)
OperationalError: (1045, u"Access denied for user 'dataesp'@'localhost' (using password: YES)")
2017-06-13 23:39:37,503 (e:\Temp\python) [log.py:151] INFO <=> Using Software Version: commit string could not be parsed, not valid json
2017-06-13 23:39:40,266 (e:\Temp\python) [log.py:151] INFO <=> Using Software Version: commit string could not be parsed, not valid json
2017-06-13 23:43:08,743 (e:\Temp\python) [log.py:78] ERROR <=> {}
Traceback (most recent call last):
  File "e:\Temp\python\Current Source Code - clickMD.ca\userapi.py", line 468, in activateAccountPost
    server.sendmail(app.config["MAIL_USERNAME"], results_dict_admins, msgAsString )
  File "C:\Python27\lib\smtplib.py", line 747, in sendmail
    raise SMTPRecipientsRefused(senderrs)
SMTPRecipientsRefused: {}
2017-06-13 23:44:58,272 (e:\Temp\python) [log.py:151] INFO <=> Using Software Version: commit string could not be parsed, not valid json
2017-06-13 23:56:36,628 (e:\Temp\python) [log.py:78] ERROR <=> {}
Traceback (most recent call last):
  File "e:\Temp\python\Current Source Code - clickMD.ca\userapi.py", line 468, in activateAccountPost
    server.sendmail(app.config["MAIL_USERNAME"], results_dict_admins, msgAsString )
  File "C:\Python27\lib\smtplib.py", line 747, in sendmail
    raise SMTPRecipientsRefused(senderrs)
SMTPRecipientsRefused: {}
2017-06-13 23:59:06,835 (e:\Temp\python) [log.py:151] INFO <=> Using Software Version: commit string could not be parsed, not valid json
2017-06-14 00:02:49,042 (e:\Temp\python) [log.py:78] ERROR <=> (1146, u"Table 'clickmd.doctor' doesn't exist")
Traceback (most recent call last):
  File "e:\Temp\python\Current Source Code - clickMD.ca\userapi.py", line 1441, in getDoctorOnCall
    cursor.execute(query)
  File "C:\Python27\lib\site-packages\pymysql\cursors.py", line 166, in execute
    result = self._query(query)
  File "C:\Python27\lib\site-packages\pymysql\cursors.py", line 322, in _query
    conn.query(q)
  File "C:\Python27\lib\site-packages\pymysql\connections.py", line 856, in query
    self._affected_rows = self._read_query_result(unbuffered=unbuffered)
  File "C:\Python27\lib\site-packages\pymysql\connections.py", line 1057, in _read_query_result
    result.read()
  File "C:\Python27\lib\site-packages\pymysql\connections.py", line 1340, in read
    first_packet = self.connection._read_packet()
  File "C:\Python27\lib\site-packages\pymysql\connections.py", line 1014, in _read_packet
    packet.check_error()
  File "C:\Python27\lib\site-packages\pymysql\connections.py", line 393, in check_error
    err.raise_mysql_exception(self._data)
  File "C:\Python27\lib\site-packages\pymysql\err.py", line 107, in raise_mysql_exception
    raise errorclass(errno, errval)
ProgrammingError: (1146, u"Table 'clickmd.doctor' doesn't exist")
2017-06-14 00:03:13,865 (e:\Temp\python) [log.py:78] ERROR <=> (1146, u"Table 'clickmd.doctor' doesn't exist")
Traceback (most recent call last):
  File "e:\Temp\python\Current Source Code - clickMD.ca\userapi.py", line 1441, in getDoctorOnCall
    cursor.execute(query)
  File "C:\Python27\lib\site-packages\pymysql\cursors.py", line 166, in execute
    result = self._query(query)
  File "C:\Python27\lib\site-packages\pymysql\cursors.py", line 322, in _query
    conn.query(q)
  File "C:\Python27\lib\site-packages\pymysql\connections.py", line 856, in query
    self._affected_rows = self._read_query_result(unbuffered=unbuffered)
  File "C:\Python27\lib\site-packages\pymysql\connections.py", line 1057, in _read_query_result
    result.read()
  File "C:\Python27\lib\site-packages\pymysql\connections.py", line 1340, in read
    first_packet = self.connection._read_packet()
  File "C:\Python27\lib\site-packages\pymysql\connections.py", line 1014, in _read_packet
    packet.check_error()
  File "C:\Python27\lib\site-packages\pymysql\connections.py", line 393, in check_error
    err.raise_mysql_exception(self._data)
  File "C:\Python27\lib\site-packages\pymysql\err.py", line 107, in raise_mysql_exception
    raise errorclass(errno, errval)
ProgrammingError: (1146, u"Table 'clickmd.doctor' doesn't exist")
2017-06-14 00:04:45,927 (e:\Temp\python) [log.py:78] ERROR <=> (1146, u"Table 'clickmd.doctor' doesn't exist")
Traceback (most recent call last):
  File "e:\Temp\python\Current Source Code - clickMD.ca\userapi.py", line 1441, in getDoctorOnCall
    cursor.execute(query)
  File "C:\Python27\lib\site-packages\pymysql\cursors.py", line 166, in execute
    result = self._query(query)
  File "C:\Python27\lib\site-packages\pymysql\cursors.py", line 322, in _query
    conn.query(q)
  File "C:\Python27\lib\site-packages\pymysql\connections.py", line 856, in query
    self._affected_rows = self._read_query_result(unbuffered=unbuffered)
  File "C:\Python27\lib\site-packages\pymysql\connections.py", line 1057, in _read_query_result
    result.read()
  File "C:\Python27\lib\site-packages\pymysql\connections.py", line 1340, in read
    first_packet = self.connection._read_packet()
  File "C:\Python27\lib\site-packages\pymysql\connections.py", line 1014, in _read_packet
    packet.check_error()
  File "C:\Python27\lib\site-packages\pymysql\connections.py", line 393, in check_error
    err.raise_mysql_exception(self._data)
  File "C:\Python27\lib\site-packages\pymysql\err.py", line 107, in raise_mysql_exception
    raise errorclass(errno, errval)
ProgrammingError: (1146, u"Table 'clickmd.doctor' doesn't exist")
2017-06-14 00:15:15,299 (e:\Temp\python) [log.py:151] INFO <=> Using Software Version: commit string could not be parsed, not valid json
2017-06-14 00:15:49,858 (e:\Temp\python) [log.py:78] ERROR <=> (1146, u"Table 'clickmd.doctor' doesn't exist")
Traceback (most recent call last):
  File "e:\Temp\python\Current Source Code - clickMD.ca\userapi.py", line 1441, in getDoctorOnCall
    cursor.execute(query)
  File "C:\Python27\lib\site-packages\pymysql\cursors.py", line 166, in execute
    result = self._query(query)
  File "C:\Python27\lib\site-packages\pymysql\cursors.py", line 322, in _query
    conn.query(q)
  File "C:\Python27\lib\site-packages\pymysql\connections.py", line 856, in query
    self._affected_rows = self._read_query_result(unbuffered=unbuffered)
  File "C:\Python27\lib\site-packages\pymysql\connections.py", line 1057, in _read_query_result
    result.read()
  File "C:\Python27\lib\site-packages\pymysql\connections.py", line 1340, in read
    first_packet = self.connection._read_packet()
  File "C:\Python27\lib\site-packages\pymysql\connections.py", line 1014, in _read_packet
    packet.check_error()
  File "C:\Python27\lib\site-packages\pymysql\connections.py", line 393, in check_error
    err.raise_mysql_exception(self._data)
  File "C:\Python27\lib\site-packages\pymysql\err.py", line 107, in raise_mysql_exception
    raise errorclass(errno, errval)
ProgrammingError: (1146, u"Table 'clickmd.doctor' doesn't exist")
